Workbook
Name C_001_A003: #REF!
Name C_001_A003: #REF!
Name C_001_A004: #REF!
Name C_001_A004: #REF!
Name C_001_A006: #REF!
Name C_001_A006: #REF!
Name C_001_B001: #REF!
Name C_001_B001: #REF!
Name DB_BLOCK_SIZE: #REF!
Name DB_BLOCK_SIZE: #REF!
Name DB_TYPE: [2]各種データ!$A$2:$A$6
Name DBMS: [3]マスタ!$B$3:$B$5
Name DBMS: [4]マスタ!$B$3:$B$5
Name DB名: [3]マスタ!$D$3:$D$11
Name DB名: [4]マスタ!$D$3:$D$11
Name EDELIVE_AGREEMENT_KBN: #REF!
Name MAIL_BM_FLG: #REF!
Name MYSQL_DATA_TYPE: [2]各種データ!$D$2:$D$30
Name NotNull: #REF!
Name NotNull: #REF!
Name NotNull: #REF!
Name ORACLE_DATA_TYPE: [2]各種データ!$B$2:$B$20
Name POSTGRESQL_DATA_TYPE: [2]各種データ!$F$2:$F$25
Name SELECTED_DB: #REF!
Name SELECTED_DB: #REF!
Name SQLITE_DATA_TYPE: [2]各種データ!$E$2:$E$6
Name SQLSVR_DATA_TYPE: [2]各種データ!$C$2:$C$31
Name TABLE_LIST: #REF!
Name TABLE_LIST: #REF!
Name TABLE_LIST_DEF: #REF!
Name TABLE_LIST_DEF: #REF!
Name インデックス情報: #REF!
Name インデックス情報: #REF!
Name インデックス情報: #REF!
Name カラム情報: #REF!
Name カラム情報: #REF!
Name カラム情報: #REF!
Name サービス: [3]マスタ!$G$3:$G$26
Name サービス: [4]マスタ!$G$3:$G$26
Name スキーマ名: [3]マスタ!$E$3:$E$21
Name スキーマ名: [4]マスタ!$E$3:$E$21
Name スキーマ名入力: #REF!
Name スキーマ名入力: #REF!
Name スキーマ名入力: #REF!
Name データサイクル: [3]マスタ!$H$3:$H$6
Name データサイクル: [4]マスタ!$H$3:$H$6
Name データ型: [5]マスタ!$C$3:$C$13
Name データ型: [6]マスタ!$C$3:$C$8
Name テーブル情報: #REF!
Name テーブル情報: #REF!
Name テーブル情報: #REF!
Name テーブル種別: [3]マスタ!$I$3:$I$7
Name テーブル種別: [4]マスタ!$I$3:$I$5
Name 入力チェック: #REF!
Name 入力チェック: #REF!
Name 分類: [3]マスタ!$F$3:$F$12
Name 分類: [4]マスタ!$F$3:$F$12
Name 物理テーブル名入力: #REF!
Name 物理テーブル名入力: #REF!
Name 物理テーブル名入力: #REF!

Sheet 表紙
J13: =J52 -> 電子交付同意データ登録
J25: =J53 -> 46155
AW45: Ver1.00
C51: ドキュメント情報
D52: ドキュメント名称 | J52: 電子交付同意データ登録
D53: 作成更新日 | J53: =MAX(変更履歴!E4:E33) -> 46155

Sheet 変更履歴
A1: 変更履歴
B3: No | C3: ver | D3: 課題管理番号 | E3: 変更日付 | F3: 変更者 | G3: シート名 | H3: 変更内容 | I3: 変更区分 | J3: 承認日付 | K3: 承認者 | L3: 備考
B4: 0001 | C4: 1.00 | D4: EM003404 | E4: 46155 | F4: SBIFPTフック | G4: 全体 | H4: 新規作成 | I4: 新規作成

Sheet 目次
A1: 目次
B3: No | C3: シート | D3: 要不要 | E3: 補足（Action詳細シートの場合のアクション名称など）
B4: 1 | C4: 表紙
B5: 2 | C5: 変更履歴
B6: 3 | C6: 目次
B7: 4 | C7: 概要
B8: 5 | C8: 画面レイアウト
B9: 6 | C9: 画面項目定義
B10: 7 | C10: Action定義
B11: 8 | C11: Actionパラメータ
B12: 9 | C12: API詳細 | D12: 不要
B13: 10 | C13: 共通関数詳細 | D13: 不要
B14: 11 | C14: SQL定義
B15: 12 | C15: ファイル項目定義(CSV出力) | D15: 不要
B16: 13 | C16: ファイル項目定義(ファイル取込) | D16: 不要
B17: 14 | C17: 入力チェック
B18: 15 | C18: アップロード用テンプレート説明

Sheet 概要
Q1: 削除区分 | R1: 課題管理番号 | S1: 変更内容 | T1: （レビュー管理No） | U1: 変更履歴紐づけ
B2: 処理概要
C7: 画面遷移
E8: ActionID | F8: 画面ID | G8: 画面日本語名称 | H8: 遷移 | I8: 遷移先ActionID | J8: 画面遷移パターン | K8: 備考
E9: - | F9: SUB0504_02-01 | G9: 電子交付同意データ登録 | H9: 遷移元 | I9: - | J9: 一覧画面遷移
C11: 共通関数
E12: 共通関数ID | F12: 共通関数名称 | G12: 共通関数日本語名称 | K12: 参照 | L12: 更新 | M12: 備考
E13: なし | K13: - | L13: -
C15: API
E16: APIID | F16: API名称 | G16: API日本語名称 | J16: 接続先 | K16: 参照 | L16: 更新 | M16: 備考
E17: なし | K17: - | L17: -
C19: SQL
E20: SQLID | F20: SQL名称 | G20: SQL日本語名称 | H20: スキーマ | I20: テーブル名称 | J20: テーブル日本語名称 | K20: 参照 | L20: 登録 | M20: 更新 | N20: 削除 | O20: 備考
E21: SQL001 | G21: 顧客属性情報取得 | H21: CORDYS | I21: MEDIATE_USER_ATTRIBUTE_INFO | J21: 仲介業者顧客口座属性 | K21: 〇 | L21: - | M21: - | N21: -
E22: SQL002 | G22: 電子交付承諾情報登録更新 | H22: CORDYS | I22: T_IPO_PO_EDELIV_AGRMNT | J22: IPO・PO電子交付承諾 | K22: - | L22: 〇 | M22: 〇 | N22: -

Sheet 画面レイアウト
CD1: 削除区分 | CE1: 課題管理番号 | CF1: 変更内容 | CG1: （レビュー管理No） | CH1: 変更履歴紐づけ
B3: ■電子交付同意データ一覧

Sheet 画面項目定義
Z1: 削除区分 | AA1: 課題管理番号 | AB1: 変更内容 | AC1: （レビュー管理No） | AD1: 変更履歴紐づけ | AE1: 項目名見直し対象 | AF1: 項目名見直し内容
B2: No. | D2: 項目名 | E2: ラベル | F2: 共通部品ID | G2: ドメインID | H2: コントロール | I2: 設定元 | K2: 編集内容 | L2: 配置 | N2: I/O | O2: 入力形式/表示形式 | P2: 固定長 可変長 | Q2: 表示最大桁数 | R2: 数値範囲 | U2: 活性 | V2: 初期値 | W2: アクションID | X2: 備考
I3: アクションID | J3: 項目 | L3: 上下 | M3: 左右 | R3: 最小値 | S3: 最大値 | T3: 単位
B4: =ROW()-3 -> 1 | C4: タイトルエリア
B5: =ROW()-3 -> 2 | D5: タイトル | E5: 電子交付同意データ登録 | F5: - | G5: - | H5: ラベル | I5: - | J5: - | K5: - | L5: 中央 | M5: 左 | N5: O | O5: -//-
B6: =ROW()-3 -> 3 | C6: 検索条件部
B7: =ROW()-3 -> 4 | D7: ファイル選択 | E7: ファイル選択 | F7: CS025 | G7: - | H7: ボタン | I7: A001 | J7: - | K7: - | L7: 中央 | M7: 中央 | N7: I | O7: -//- | U7: 〇 | W7: -
B8: =ROW()-3 -> 5 | C8: 電子交付同意データ一覧 | H8: データグリッド
B9: =ROW()-3 -> 6 | D9: 確認 | F9: CS001 | H9: ボタン | I9: A002 | J9: - | K9: ファイルパスが未入力の場合、「確認」ボタンは非活性とする。 入力された場合、「確認」ボタンは活性とする。 | L9: 中央 | M9: 中央 | O9: - | U9: ▲
B10: =ROW()-3 -> 7 | D10: 登録 | F10: CS001 | H10: ボタン | I10: A003 | J10: - | K10: 初期表示：非活性 OKデータが存在する場合のみ、活性とする | L10: 中央 | M10: 中央 | O10: - | U10: ▲
B11: =ROW()-3 -> 8 | D11: NGダウンロード | F11: CS001 | H11: ボタン | I11: A004 | J11: - | K11: 初期表示：非活性 NGデータが存在する場合のみ、活性とする | L11: 中央 | M11: 中央 | O11: - | U11: ▲
B12: =ROW()-3 -> 9 | D12: クリア | F12: CS001 | H12: ボタン | I12: A005 | J12: - | L12: 中央 | M12: 中央 | O12: - | U12: 〇
B13: =ROW()-3 -> 10 | D13: タイトル | E13: 電子交付同意データ一覧 | F13: - | G13: - | H13: ラベル | L13: 中央 | M13: 中央 | N13: - | O13: -
B14: =ROW()-3 -> 11 | D14: 部店 | E14: 部店 | F14: - | G14: - | H14: ラベル | L14: 中央 | M14: 中央 | N14: - | O14: - | P14: - | Q14: - | R14: - | S14: - | T14: - | U14: - | V14: - | W14: -
B15: =ROW()-3 -> 12 | F15: - | G15: - | H15: テキスト | I15: A002 | J15: 電子交付同意データ一覧.部店 | L15: 中央 | M15: 中央 | N15: O | O15: - | P15: - | Q15: - | R15: - | S15: - | T15: - | U15: - | V15: - | W15: -
B16: =ROW()-3 -> 13 | D16: 口座番号 | E16: 口座番号 | F16: - | G16: - | H16: ラベル | L16: 中央 | M16: 中央 | N16: - | O16: - | P16: - | Q16: - | R16: - | S16: - | T16: - | U16: - | V16: - | W16: -
B17: =ROW()-3 -> 14 | F17: - | G17: - | H17: テキスト | I17: A002 | J17: 電子交付同意データ一覧.口座番号 | L17: 中央 | M17: 左 | N17: O | O17: - | P17: - | Q17: - | R17: - | S17: - | T17: - | U17: - | V17: - | W17: -
B18: =ROW()-3 -> 15 | D18: 電子交付承諾日付 | E18: 電子交付承諾日付 | F18: - | G18: - | H18: ラベル | L18: 中央 | M18: 中央 | N18: - | O18: - | P18: - | Q18: - | R18: - | S18: - | T18: - | U18: - | V18: - | W18: -
B19: =ROW()-3 -> 16 | F19: - | G19: - | H19: テキスト | I19: A002 | J19: 電子交付同意データ一覧.電子交付承諾日付 | L19: 中央 | M19: 左 | N19: O | O19: YYYY/MM/DD | P19: - | Q19: - | R19: - | S19: - | T19: - | U19: - | V19: - | W19: -
B20: =ROW()-3 -> 17 | D20: 電子交付承諾区分 | E20: 電子交付承諾区分 | F20: - | G20: - | H20: ラベル | L20: 中央 | M20: 中央 | N20: - | O20: - | P20: - | Q20: - | R20: - | S20: - | T20: - | U20: - | V20: - | W20: -
B21: =ROW()-3 -> 18 | F21: - | G21: - | H21: テキスト | I21: A002 | J21: 電子交付同意データ一覧.電子交付承諾区分 | L21: 中央 | M21: 左 | N21: O | O21: - | P21: - | Q21: - | R21: - | S21: - | T21: - | U21: - | V21: - | W21: -
B22: =ROW()-3 -> 19 | D22: チェック結果 | E22: チェック結果 | F22: - | G22: - | H22: ラベル | K22: 0：未承諾 1：承諾済 | L22: 中央 | M22: 中央 | N22: - | O22: - | P22: - | Q22: - | R22: - | S22: - | T22: - | U22: - | V22: - | W22: -
B23: =ROW()-3 -> 20 | F23: - | G23: - | H23: テキスト | I23: A002 | J23: 電子交付同意データ一覧.チェック結果 | K23: "「NGあり」の場合、リンクを表示する。（A006） 「OK」の場合、テキストのみを表示する。 リンク押下時、チェック結果に応じたチェックメッセージを表示する。 | L23: 中央 | M23: 左 | N23: O | O23: - | P23: - | Q23: - | R23: - | S23: - | T23: - | U23: - | V23: - | W23: -
B24: =ROW()-3 -> 21 | C24: Hidden項目
B25: =ROW()-3 -> 22 | D25: メッセージを表示する | H25: hidden | I25: A002 | J25: 目論見書閲覧データ一覧.メッセージを表示する | N25: O

Sheet Action定義
L1: 削除区分 | M1: 課題管理番号 | N1: 変更内容 | O1: （レビュー管理No） | P1: 変更履歴紐づけ
B2: アクションID | C2: アクション名称 | E2: 処理概要 | G2: 処理概要 | H2: 呼出機能 | I2: メッセージID | J2: 備考
B3: A001 | C3: ファイル選択押下 | D3: 1 | E3: Lấy đường dẫn file cần đăng ký và hiển thị vào ô nhập đường dẫn file
B4: =B3 -> A001 | C4: =C3 -> ファイル選択押下 | E4: Nút 【確認】 được kích hoạt (Active)
B5: A002 | C5: 確認押下 | D5: 1 | E5: Thực hiện kiểm tra định dạng file Excel
E6: Nếu không file có phần mở rộng “.xls” hoặc “.xlsx”
E7: Hiển thị thông báo lỗi | I7: errors.notExcelFile | J7: 「xlsまたはxlsxファイル以外が選択されています。」
D8: 2 | E8: Kiểm tra file có password
E9: Nếu file được đặt password
E10: Hiển thị thông báo lỗi | I10: errors.hasPassword | J10: 「Excelファイルを取込むことができません（パスワード付き）。ご確認ください。」
D11: 3 | E11: Kiểm tra tên sheet
E12: Nếu file có từ 1 sheet trở lên
E13: Kiểm tra sự tồn tại của sheet 「電子交付同意」
E14: Nếu không tồn tại thi Phát sinh lỗi | I14: errors.sheetNotExist | J14: {0}:「電子交付同意」
D15: 4 | E15: Đọc dữ liệu từ file Excel và thực hiện kiểm tra
E16: 4.1 Kiểm tra file có ít nhất 1 dòng dữ liệu (không tính header) | I16: info.orderedDataNotExist | J16: {0}: 「明細」
E17: 4.2 Kiểm tra số lượng tối đa
E18: Nếu số dòng từ dòng 2 trở đi ≥ 2000 (không tính dòng trống) Phát sinh lỗi | I18: errors.maxUpload | J18: {0}: 「2000」
D19: 5 | E19: Kiểm tra từng dòng dữ liệu
E20: Lấy từng dòng và thực hiện các kiểm tra từ 5.3 ~ 5.4
E21: Kết quả được lưu vào danh sách hiển thị
E22: 5.3 Kiểm tra input
E23: Tham chiếu sheet 「入力チェック」
E24: 5.4 Kiểm tra tồn tại 部店 +口座番号 | H24: SQL001
E25: Chỉ thực hiện nếu kết quả input check = OK
E26: Nếu COUNT = 0 lưu lại lỗi | I26: errors.butenAccountNotExist
E27: Nếu không có lỗi Gán giá trị 【チェック結果】 = "OK"
D28: 6 | E28: Điều khiển trạng thái nút
E29: Nếu tồn tại dòng có trạng thái "OK" Nút 【登録】 được kích hoạt
E30: Nếu tồn tại dòng có lỗi (NG) Nút 【NGダウンロード】 được kích hoạt
D31: 7 | E31: trong quá trình xử lý phát sinh → trả về lỗi hệ thống | I31: errors.serverError
B32: A003 | C32: 登録押下 | D32: 1 | E32: Thực hiện kiểm tra số lượng dữ liệu cần đăng ký | H32: SQL002
E33: Trường hợp bằng 0:
E34: Thiết lập thông báo lỗi và kết thúc xử lý | I34: info.orderedDataNotExist | J34: OK
D35: 2 | E35: Trường hợp có từ 1 bản ghi trở lên
E36: Thực hiện xử lý đăng ký dữ liệu
E37: Nếu dữ liệu có kết quả check là "OK" và tồn tại trong DB thì thực hiện cập nhật.
E38: Nếu dữ liệu "OK" không tồn tại trong DB thì thực hiện đăng ký (insert).
D39: 3 | E39: Kiểm tra kết quả xử lý đăng ký
E40: Trường hợp xử lý thành công
...

Sheet Actionパラメータ
H1: ○：必須、●：条件付き必須 | N1: 削除区分 | O1: 課題管理番号 | P1: 変更内容 | Q1: （レビュー管理No） | R1: 変更履歴紐づけ
B2: アクションID | C2: アクション名称 | D2: 画面from | E2: 画面to | F2: 種別 | G2: 項目名称 | H2: 必須 | I2: 設定元 | K2: 編集内容 | L2: 備考
I3: 呼出機能 | J3: 項目
B4: A001 | C4: =VLOOKUP(B4,[9]Action定義!B:C,2,0) -> ファイル選択押下 | D4: 遷移元画面 | E4: 自画面 | F4: リクエスト | G4: ファイル選択 | H4: 〇 | I4: 画面 | J4: ファイル選択
B5: A002 | C5: =VLOOKUP(B5,Action定義!B:C,2,0) -> 確認押下 | D5: 自画面 | E5: 自画面 | F5: レスポンス | G5: 部店 | H5: - | I5: API_A002 | J5: 部店
B6: =B5 -> A002 | C6: =VLOOKUP(B6,Action定義!B:C,2,0) -> 確認押下 | D6: 自画面 | E6: 自画面 | F6: レスポンス | G6: 口座番号 | H6: - | I6: API_A002 | J6: 口座番号
B7: =B6 -> A002 | C7: =VLOOKUP(B7,Action定義!B:C,2,0) -> 確認押下 | D7: 自画面 | E7: 自画面 | F7: レスポンス | G7: 電子交付承諾日付 | H7: - | I7: API_A002 | J7: 電子交付承諾日付
B8: =B6 -> A002 | C8: =VLOOKUP(B8,Action定義!B:C,2,0) -> 確認押下 | D8: 自画面 | E8: 自画面 | F8: レスポンス | G8: 電子交付承諾区分 | H8: - | I8: API_A002 | J8: 電子交付承諾区分
B9: =B7 -> A002 | C9: =VLOOKUP(B9,Action定義!B:C,2,0) -> 確認押下 | D9: 自画面 | E9: 自画面 | F9: レスポンス | G9: チェック結果 | H9: - | I9: API_A002 | J9: チェック結果
B10: =B7 -> A002 | C10: =VLOOKUP(B10,Action定義!B:C,2,0) -> 確認押下 | D10: 自画面 | E10: 自画面 | F10: レスポンス | G10: メッセージを表示する | H10: - | I10: API_A002 | J10: メッセージを表示する
B11: A003 | C11: =VLOOKUP(B11,[9]Action定義!B:C,2,0) -> 登録押下 | D11: 自画面 | E11: 自画面 | F11: リクエスト | G11: 部店 | H11: - | I11: 画面 | J11: 部店
B12: =B11 -> A003 | C12: =VLOOKUP(B12,[9]Action定義!B:C,2,0) -> 登録押下 | D12: 自画面 | E12: 自画面 | F12: リクエスト | G12: 口座番号 | H12: - | I12: 画面 | J12: 口座番号
B13: =B12 -> A003 | C13: =VLOOKUP(B13,[9]Action定義!B:C,2,0) -> 登録押下 | D13: 自画面 | E13: 自画面 | F13: リクエスト | G13: 電子交付承諾日付 | H13: - | I13: 画面 | J13: 電子交付承諾日付
B14: =B13 -> A003 | C14: =VLOOKUP(B14,[9]Action定義!B:C,2,0) -> 登録押下 | D14: 自画面 | E14: 自画面 | F14: リクエスト | G14: 電子交付承諾区分 | H14: - | I14: 画面 | J14: 電子交付承諾区分
B15: =B14 -> A003 | C15: =VLOOKUP(B15,[9]Action定義!B:C,2,0) -> 登録押下 | D15: 自画面 | E15: 自画面 | F15: リクエスト | G15: チェック結果 | H15: - | I15: 画面 | J15: チェック結果
B16: =B15 -> A003 | C16: =VLOOKUP(B16,[9]Action定義!B:C,2,0) -> 登録押下 | D16: 自画面 | E16: 自画面 | F16: リクエスト | G16: メッセージを表示する | H16: - | I16: 画面 | J16: メッセージを表示する
B17: A003 | C17: =VLOOKUP(B17,[9]Action定義!B:C,2,0) -> 登録押下 | D17: 自画面 | E17: 自画面 | F17: レスポンス | G17: 部店 | H17: - | I17: API-A003 | J17: 部店
B18: =B17 -> A003 | C18: =VLOOKUP(B18,[9]Action定義!B:C,2,0) -> 登録押下 | D18: 自画面 | E18: 自画面 | F18: レスポンス | G18: 口座番号 | H18: - | I18: API-A003 | J18: 口座番号
B19: =B18 -> A003 | C19: =VLOOKUP(B19,[9]Action定義!B:C,2,0) -> 登録押下 | D19: 自画面 | E19: 自画面 | F19: レスポンス | G19: 電子交付承諾区分 | H19: - | I19: API-A003 | J19: 電子交付承諾区分
B20: =B19 -> A003 | C20: =VLOOKUP(B20,[9]Action定義!B:C,2,0) -> 登録押下 | D20: 自画面 | E20: 自画面 | F20: レスポンス | G20: メッセージを表示する | H20: - | I20: API-A003 | J20: メッセージを表示する
B21: =B20 -> A003 | C21: =VLOOKUP(B21,[9]Action定義!B:C,2,0) -> 登録押下 | D21: 自画面 | E21: 自画面 | F21: レスポンス | G21: チェック結果 | H21: - | I21: API-A003 | J21: チェック結果
B22: =B21 -> A003 | C22: =VLOOKUP(B22,[9]Action定義!B:C,2,0) -> 登録押下 | D22: 自画面 | E22: 自画面 | F22: レスポンス | G22: 電子交付承諾日付 | H22: - | I22: API-A003 | J22: 電子交付承諾日付
B23: =B22 -> A003 | C23: =VLOOKUP(B23,[9]Action定義!B:C,2,0) -> 登録押下 | D23: 自画面 | E23: 自画面 | F23: レスポンス | G23: 電子交付承諾区分漢字 | H23: - | I23: API-A003 | J23: 電子交付承諾区分漢字
B24: A004 | C24: =VLOOKUP(B24,[9]Action定義!B:C,2,0) -> NGダウンロード押下 | D24: 自画面 | E24: 自画面 | F24: リクエスト | G24: NGダウンロード | H24: 〇 | I24: 画面 | J24: NGダウンロード
B25: A005 | C25: =VLOOKUP(B25,[9]Action定義!B:C,2,0) -> クリア押下 | D25: 自画面 | E25: 自画面 | F25: リクエスト | G25: クリア | H25: 〇 | I25: 画面 | J25: クリア
B26: A006 | C26: =VLOOKUP(B26,[9]Action定義!B:C,2,0) -> NGあり押下 | D26: 自画面 | E26: 自画面 | F26: リクエスト | G26: NGあり | H26: 〇 | I26: 画面 | J26: NGあり

Sheet SQL定義
L1: 削除区分 | M1: 課題管理番号 | N1: 変更内容 | O1: （レビュー管理No） | P1: 変更履歴紐づけ
B2: SQL001. 顧客属性情報取得
C4: ＜SQL概要＞
C5: MEDIATE_USER_ATTRIBUTE_INFOテーブルに対し、 支店コードおよび口座番号を条件にデータ件数を取得する。
C8: SQL概要 | E8: SQL仕様 | J8: 備考
C9: 【適用条件】 | E9: 【取得項目】 | I9: SELECT
D10: なし | F10: COUNT(1) AS 件数 | I10: count(1)
E11: 【テーブル】 | I11: FROM
C12: 【SQL種別】 | F12: 仲介業者顧客口座属性 A | I12: MEDIATE_USER_ATTRIBUTE_INFO MUAI
D13: 検索 | I13: WHERE
E14: 【抽出条件】 | I14: 1 = 1
C15: 【抽出件数】 | F15: A.部店コード = 該当行目の部店コード 且つ A.口座番号 = 該当行目の口座番号 | I15: AND MUAI.BUTEN_CODE = #{butenCode},
D16: 0 or 複数件 | I16: AND MUAI.ACCOUNT_NUMBER = TO_NUMBER(#{accountNumber})
C18: 【排他獲得】
D19: 不要
C21: 【備考】
D22: 特になし
B27: SQL002.電子交付承諾情報登録更新
C29: ＜SQL概要＞
C30: 削除： 【IPO・PO電子交付承諾】テーブルに対する登録・更新処理
C33: SQL概要 | E33: SQL仕様 | J33: 備考
C34: 【適用条件】 | E34: 【更新項目】 | G34: 【設定内容】 | I34: MERGE INTO T_IPO_PO_EDELIV_AGRMNT TIPEA
D35: なし | F35: 電子交付承諾日付 | H35: 画面表示リスト.電子交付承諾日付 | I35: USING
F36: 電子交付承諾区分 | H36: 画面表示リスト.電子交付承諾区分 ※1：承諾済 0：未承諾 | I36: (
C37: 【SQL種別】 | F37: 更新日 | H37: システム日付 | I37: SELECT | J37: IFA_DATE_UTIL.IFA_GET_DATE()
D38: 削除 | F38: 更新者 | H38: ログインユーザID | I38: #{param.butenCode} AS BUTEN_CODE,
F39: 機能ID | H39: 機能ID | I39: #{param.accountNumber} AS ACCOUNT_NUMBER, | J39: "SUB0504"
C40: 【抽出件数】 | I40: TO_DATE(#{param.edelivAgreementDate}, 'YYYY/MM/DD') AS EDELIV_AGREEMENT_DATE,
D41: - | E41: 【設定項目】 | G41: 【設定内容】 | I41: #{param.edelivAgreementKbn} AS EDELIV_AGREEMENT_KBN,
F42: 部店 | H42: 画面表示リスト.部店 | I42: #{param.userId} AS USER_ID
C43: 【排他獲得】 | F43: 口座番号 | H43: 画面表示リスト.口座番号 | I43: FROM DUAL
D44: 不要 | F44: 電子交付承諾日付 | H44: 画面表示リスト.電子交付承諾日付 | I44: ) A
F45: 電子交付承諾区分 | H45: 画面表示リスト.電子交付承諾区分 ※1：承諾済 0：未承諾 | I45: ON (
C46: 【備考】 | F46: 作成日 | H46: システム日付 | I46: TIPEA.BUTEN_CODE = A.BUTEN_CODE | J46: IFA_DATE_UTIL.IFA_GET_DATE()
D47: 特になし | F47: 作成者 | H47: ログインユーザID | I47: AND TIPEA.ACCOUNT_NUMBER = A.ACCOUNT_NUMBER
F48: 更新日 | H48: システム日付 | I48: ) | J48: IFA_DATE_UTIL.IFA_GET_DATE()
F49: 更新者 | H49: ログインユーザID | I49: WHEN MATCHED THEN
F50: 機能ID | H50: 機能ID | I50: UPDATE SET | J50: "SUB0504"
I51: TIPEA.EDELIV_AGREEMENT_DATE = A.EDELIV_AGREEMENT_DATE,
I52: TIPEA.EDELIV_AGREEMENT_KBN = A.EDELIV_AGREEMENT_KBN,
...

Sheet アップロード用テンプレート説明
B2: 1.シートの内容イメージ
B13: 2.シート(「電子交付同意」)の項目説明
C15: No | D15: 項目名 | O15: 必須 | P15: 入力形式/表示形式 | W15: 最大桁数 | Z15: 備考
C16: 1 | D16: 1行目固定：ヘッダー部 | O16: ○ | P16: - | W16: - | Z16: 名前固定
C17: 4 | E17: 部店 | O17: ○ | P17: 文字列 | W17: - | Z17: 名前固定
C18: 5 | E18: 口座番号 | O18: ○ | P18: 文字列 | W18: - | Z18: 名前固定
C19: 6 | E19: 電子交付承諾日付 | O19: ○ | P19: 文字列 | W19: - | Z19: 名前固定
C20: 7 | E20: 電子交付承諾区分 | O20: ○ | P20: 文字列 | W20: - | Z20: 名前固定
C21: 10 | D21: 2行目以降： データ入力部
C22: 11 | E22: 部店 | O22: ○ | P22: 英数字のみ | W22: 3
C23: 12 | E23: 口座番号 | O23: ○ | P23: 半角数字のみ | W23: 6
C24: 13 | E24: 電子交付承諾日付 | O24: - | P24: yyyy/mm/ddのみ | W24: -
C25: 14 | E25: 電子交付承諾区分 | O25: ○ | P25: 半角数字のみ | W25: 1

Sheet 入力チェック
B2: No | D2: 項目名 | J2: チェック | S2: メッセージID | AD2: メッセージ | AZ2: 第１引数 | BE2: 第２引数 | BM2: 第３引数 | BR2: 第４引数 | BW2: 備考
B3: 1 | D3: 部店 | J3: 必須入力チェック | S3: errors.required | AD3: {0}を入力してください。 | AZ3: 部店 | BW3: BE
B4: =B3+1 -> 2 | D4: 部店コード | J4: 半角英数字のみチェック | S4: errors.type | AD4: {0}は{1}を入力してください。 | AZ4: 部店 | BE4: 半角英数字 | BW4: BE
B5: =B4+1 -> 3 | D5: 部店コード | J5: 桁数チェック(最大3桁) | S5: errors.maxSize | AD5: {0}は{1}桁以下で入力してください。 | AZ5: 部店 | BE5: 3 | BW5: BE
B6: =B5+1 -> 4 | D6: 口座番号 | J6: 必須入力チェック | S6: errors.required | AD6: {0}を入力してください。 | AZ6: 口座番号 | BW6: BE
B7: =B6+1 -> 5 | D7: 口座番号 | J7: 半角数字のみチェック | S7: errors.type | AD7: {0}は{1}を入力してください。 | AZ7: 口座番号 | BE7: 半角数字 | BW7: BE
B8: =B7+1 -> 6 | D8: 口座番号 | J8: 桁数チェック(最大6桁) | S8: errors.maxSize | AD8: {0}は{1}桁以下で入力してください。 | AZ8: 口座番号 | BE8: 6 | BW8: BE
B9: =B8+1 -> 7 | D9: 電子交付承諾日付 | J9: 正しい日付で入力チェック | S9: errors.date.specifyFormat | AD9: {0}を"{1}"の形式で正しい日付で入力してください。 | AZ9: 電子交付承諾日付 | BE9: YYYY/MM/DD | BW9: BE
B10: =B9+1 -> 8 | D10: 電子交付承諾区分 | J10: 必須入力チェック | S10: errors.required | AD10: {0}を入力してください。 | AZ10: 電子交付承諾区分 | BW10: BE
B11: =B10+1 -> 9 | D11: =D10 -> 電子交付承諾区分 | J11: 正しい形式で入力チェック | S11: errors.numberFormat | AD11: {0}を"{1}"の形式で入力してください。 | AZ11: 電子交付承諾区分 | BE11: 0、1 | BW11: BE

Sheet リスト
A1: プルダウンリストの値
A4: ■「概要」シート | D4: ■「画面項目定義」シート | I4: ■「画面項目定義」シート | L4: ■「画面遷移パラメータ」シート | O4: ■「ファイル項目定義(CSV出力)」シート | R4: ■「ファイル項目定義(ファイル取込)」シート | U4: ■「API詳細」「共通関数詳細」シート
A5: 〇画面遷移 | D5: 〇コントロール | I5: 〇コントロール | L5: 〇型 | O5: 〇入力形式 | R5: 〇入力形式 | U5: 〇入出力
A6: 項番 | B6: 値 | D6: 項番 | E6: 値 | I6: 項番 | J6: 値 | L6: 項番 | M6: 値 | O6: 項番 | P6: 値 | R6: 項番 | S6: 値 | U6: 項番 | V6: 値
A7: 1 | B7: 遷移元 | D7: 1 | E7: 新規作成 | I7: 1 | J7: ラベル | L7: 1 | M7: ラベル | O7: 1 | P7: YYYY-MM-DD | R7: 1 | S7: YYYY-MM-DD | U7: 1 | V7: IN
A8: 2 | B8: 遷移先 | D8: 2 | E8: 変更 | I8: 2 | J8: テキスト | L8: 2 | M8: テキスト | O8: 2 | P8: YYYY/MM/DD | R8: 2 | S8: YYYY/MM/DD | U8: 2 | V8: OUT
A9: 3 | B9: - | D9: 3 | E9: 削除 | I9: 3 | J9: テキストボックス | L9: 3 | M9: テキストボックス | O9: 3 | P9: 数字のみ | R9: 3 | S9: 数字のみ | U9: 3 | V9: -
I10: 4 | J10: テキストエリア | L10: 4 | M10: テキストエリア | O10: 4 | P10: 半角英数字のみ | R10: 4 | S10: 半角英数字のみ
A11: 〇API/共通関数/SQL機能 | I11: 5 | J11: チェックボックス | L11: 5 | M11: チェックボックス | O11: 5 | P11: 数字と小数点 | R11: 5 | S11: 数字と小数点 | U11: 〇必須
A12: 項番 | B12: 値 | I12: 6 | J12: ラジオボタン | L12: 6 | M12: ラジオボタン | O12: 6 | P12: 半角数字と小数点 | R12: 6 | S12: 半角数字と小数点 | U12: 項番 | V12: 値
A13: 1 | B13: 〇 | I13: 7 | J13: ドロップダウンリスト | L13: 7 | M13: ドロップダウンリスト | O13: 7 | P13: 数字とマイナス記号と小数点 | R13: 7 | S13: 数字とマイナス記号と小数点 | U13: 1 | V13: 〇
A14: 2 | B14: - | I14: 8 | J14: ドロップダウンリスト（複数選択） | L14: 8 | M14: ボタン | O14: 8 | P14: 英字のみ | R14: 8 | S14: 英字のみ | U14: 2 | V14: ●
I15: 9 | J15: データグリッド | L15: 9 | M15: 日付コントロール | O15: 9 | P15: 英字（大文字）のみ | R15: 9 | S15: 英字（大文字）のみ | U15: 3 | V15: -
I16: 10 | J16: データグリッド（複数選択） | L16: 10 | M16: hidden | O16: 10 | P16: 英字（小文字）のみ | R16: 10 | S16: 英字（小文字）のみ
I17: 11 | J17: ボタン | L17: 11 | M17: - | O17: 11 | P17: 英数字のみ | R17: 11 | S17: 英数字のみ
I18: 12 | J18: 日付コントロール | O18: 12 | P18: 英数字（大文字）のみ | R18: 12 | S18: 英数字（大文字）のみ
I19: 13 | J19: hidden | L19: 〇必須 | O19: 13 | P19: 英数字（小文字）のみ | R19: 13 | S19: 英数字（小文字）のみ
I20: 14 | J20: リンク | L20: 項番 | M20: 値 | O20: 14 | P20: 英数字記号のみ | R20: 14 | S20: 英数字記号のみ
I21: 15 | J21: イメージ | L21: 1 | M21: 〇 | O21: 15 | P21: 英数字記号（'"*%|以外）のみ | R21: 15 | S21: 英数字記号（'"*%|以外）のみ
I22: 16 | J22: ラジオ | L22: 2 | M22: ● | O22: 16 | P22: 0～9のみ | R22: 16 | S22: 0～9のみ
L23: 3 | M23: - | O23: 17 | P23: ひらがなのみ | R23: 17 | S23: ひらがなのみ
I24: 〇上下 | O24: 18 | P24: カタカナのみ | R24: 18 | S24: カタカナのみ
I25: 項番 | J25: 値 | L25: 〇Valited | O25: 19 | P25: 全角のみ | R25: 19 | S25: 全角のみ
I26: 1 | J26: 上 | L26: 項番 | M26: 値 | O26: 20 | P26: 全角半角 | R26: 20 | S26: 全角半角
I27: 2 | J27: 中央 | L27: 1 | M27: 〇 | O27: 21 | P27: E-mailアドレス | R27: 21 | S27: E-mailアドレス
I28: 3 | J28: 下 | L28: 2 | O28: 22 | P28: *%|以外 全て E-mailアドレス 郵便番号 全角('*%|以外)のみ | R28: 22 | S28: *%|以外 全て E-mailアドレス 郵便番号 全角('*%|以外)のみ
I29: 4 | J29: - | O29: 23 | P29: 画面構成項目（ボタン等） | R29: 23 | S29: 画面構成項目（ボタン等）
L30: 〇入力形式 | O30: 24 | P30: YYYYMMDD HH:MM | R30: 24 | S30: YYYYMMDD HH:MM
I31: 〇左右 | L31: 項番 | M31: 値 | O31: 25 | P31: ON/OFF | R31: 25 | S31: ON/OFF
I32: 項番 | J32: 値 | L32: 1 | M32: YYYY-MM-DD | O32: 26 | P32: 半角英数字、カンマのみ | R32: 26 | S32: 半角英数字、カンマのみ
I33: 1 | J33: 左 | L33: 2 | M33: YYYY/MM/DD | O33: 27 | P33: YYYYMMDD HH:MM:SS | R33: 27 | S33: YYYYMMDD HH:MM:SS
I34: 2 | J34: 中央 | L34: 3 | M34: 数字のみ | O34: 28 | P34: YYYY/MM | R34: 28 | S34: YYYY/MM
I35: 3 | J35: 右 | L35: 4 | M35: 半角英数字のみ | O35: 29 | P35: - | R35: 29 | S35: -
I36: 4 | J36: - | L36: 5 | M36: 数字と小数点
L37: 6 | M37: 半角数字と小数点
I38: 〇I/O | L38: 7 | M38: 数字とマイナス記号と小数点 | O38: 〇フォーマット | R38: 〇フォーマット
I39: 項番 | J39: 値 | L39: 8 | M39: 英字のみ | O39: 項番 | P39: 値 | R39: 項番 | S39: 値
I40: 1 | J40: I | L40: 9 | M40: 英字（大文字）のみ | O40: 1 | P40: YYYY/MM/DD | R40: 1 | S40: YYYY/MM/DD
I41: 2 | J41: O | L41: 10 | M41: 英字（小文字）のみ | O41: 2 | P41: ###,##0 | R41: 2 | S41: ###,##0
I42: 3 | J42: I/O | L42: 11 | M42: 英数字のみ | O42: 3 | P42: #####0 | R42: 3 | S42: #####0
...
